2019-02-20 19:55:30,414 ERROR: Exception on /api/users/1 [GET] [in /home/whitecx/pythonStuff/microblog/venv/lib/python3.6/site-packages/flask/app.py:1560]
Traceback (most recent call last):
  File "/home/whitecx/pythonStuff/microblog/venv/lib/python3.6/site-packages/flask/app.py", line 1982, in wsgi_app
    response = self.full_dispatch_request()
  File "/home/whitecx/pythonStuff/microblog/venv/lib/python3.6/site-packages/flask/app.py", line 1614, in full_dispatch_request
    rv = self.handle_user_exception(e)
  File "/home/whitecx/pythonStuff/microblog/venv/lib/python3.6/site-packages/flask/app.py", line 1517, in handle_user_exception
    reraise(exc_type, exc_value, tb)
  File "/home/whitecx/pythonStuff/microblog/venv/lib/python3.6/site-packages/flask/_compat.py", line 33, in reraise
    raise value
  File "/home/whitecx/pythonStuff/microblog/venv/lib/python3.6/site-packages/flask/app.py", line 1612, in full_dispatch_request
    rv = self.dispatch_request()
  File "/home/whitecx/pythonStuff/microblog/venv/lib/python3.6/site-packages/flask/app.py", line 1598, in dispatch_request
    return self.view_functions[rule.endpoint](**req.view_args)
  File "/home/whitecx/pythonStuff/microblog/app/api/users.py", line 7, in get_user
    return jsonify(User.query.get_or_404(id).to_dict())
  File "/home/whitecx/pythonStuff/microblog/app/models.py", line 107, in to_dict
    'followers': url_for('api.get_follwers', id=self.id),
  File "/home/whitecx/pythonStuff/microblog/venv/lib/python3.6/site-packages/flask/helpers.py", line 333, in url_for
    return appctx.app.handle_url_build_error(error, endpoint, values)
  File "/home/whitecx/pythonStuff/microblog/venv/lib/python3.6/site-packages/flask/app.py", line 1805, in handle_url_build_error
    reraise(exc_type, exc_value, tb)
  File "/home/whitecx/pythonStuff/microblog/venv/lib/python3.6/site-packages/flask/_compat.py", line 33, in reraise
    raise value
  File "/home/whitecx/pythonStuff/microblog/venv/lib/python3.6/site-packages/flask/helpers.py", line 323, in url_for
    force_external=external)
  File "/home/whitecx/pythonStuff/microblog/venv/lib/python3.6/site-packages/werkzeug/routing.py", line 1776, in build
    raise BuildError(endpoint, values, method, self)
werkzeug.routing.BuildError: Could not build url for endpoint 'api.get_follwers' with values ['id']. Did you mean 'api.get_followers' instead?
2019-02-20 19:56:31,887 INFO: Microblog startup [in /home/whitecx/pythonStuff/microblog/app/__init__.py:90]
2019-02-20 19:58:28,456 INFO: Microblog startup [in /home/whitecx/pythonStuff/microblog/app/__init__.py:90]
2019-02-21 12:34:45,808 INFO: Microblog startup [in /home/whitecx/pythonStuff/microblog/app/__init__.py:90]
2019-02-21 12:42:30,921 INFO: Microblog startup [in /home/whitecx/pythonStuff/microblog/app/__init__.py:90]
2019-02-21 12:56:03,967 INFO: Microblog startup [in /home/whitecx/pythonStuff/microblog/app/__init__.py:90]
2019-02-21 13:11:45,249 ERROR: Exception on /translate [POST] [in /home/whitecx/pythonStuff/microblog/venv/lib/python3.6/site-packages/flask/app.py:1560]
Traceback (most recent call last):
  File "/home/whitecx/pythonStuff/microblog/venv/lib/python3.6/site-packages/flask/app.py", line 1982, in wsgi_app
    response = self.full_dispatch_request()
  File "/home/whitecx/pythonStuff/microblog/venv/lib/python3.6/site-packages/flask/app.py", line 1614, in full_dispatch_request
    rv = self.handle_user_exception(e)
  File "/home/whitecx/pythonStuff/microblog/venv/lib/python3.6/site-packages/flask/app.py", line 1517, in handle_user_exception
    reraise(exc_type, exc_value, tb)
  File "/home/whitecx/pythonStuff/microblog/venv/lib/python3.6/site-packages/flask/_compat.py", line 33, in reraise
    raise value
  File "/home/whitecx/pythonStuff/microblog/venv/lib/python3.6/site-packages/flask/app.py", line 1612, in full_dispatch_request
    rv = self.dispatch_request()
  File "/home/whitecx/pythonStuff/microblog/venv/lib/python3.6/site-packages/flask/app.py", line 1598, in dispatch_request
    return self.view_functions[rule.endpoint](**req.view_args)
  File "/home/whitecx/pythonStuff/microblog/venv/lib/python3.6/site-packages/flask_login/utils.py", line 261, in decorated_view
    return func(*args, **kwargs)
  File "/home/whitecx/pythonStuff/microblog/app/main/routes.py", line 133, in translate_text
    request.form['dest_language'])})
  File "/home/whitecx/pythonStuff/microblog/app/translate.py", line 8, in translate
    ,dest=dest_language).text
  File "/home/whitecx/pythonStuff/microblog/venv/lib/python3.6/site-packages/googletrans/client.py", line 132, in translate
    data = self._translate(text, dest, src)
  File "/home/whitecx/pythonStuff/microblog/venv/lib/python3.6/site-packages/googletrans/client.py", line 57, in _translate
    token = self.token_acquirer.do(text)
  File "/home/whitecx/pythonStuff/microblog/venv/lib/python3.6/site-packages/googletrans/gtoken.py", line 180, in do
    self._update()
  File "/home/whitecx/pythonStuff/microblog/venv/lib/python3.6/site-packages/googletrans/gtoken.py", line 59, in _update
    code = unicode(self.RE_TKK.search(r.text).group(1)).replace('var ', '')
AttributeError: 'NoneType' object has no attribute 'group'
2019-02-21 13:11:57,812 ERROR: Exception on /translate [POST] [in /home/whitecx/pythonStuff/microblog/venv/lib/python3.6/site-packages/flask/app.py:1560]
Traceback (most recent call last):
  File "/home/whitecx/pythonStuff/microblog/venv/lib/python3.6/site-packages/flask/app.py", line 1982, in wsgi_app
    response = self.full_dispatch_request()
  File "/home/whitecx/pythonStuff/microblog/venv/lib/python3.6/site-packages/flask/app.py", line 1614, in full_dispatch_request
    rv = self.handle_user_exception(e)
  File "/home/whitecx/pythonStuff/microblog/venv/lib/python3.6/site-packages/flask/app.py", line 1517, in handle_user_exception
    reraise(exc_type, exc_value, tb)
  File "/home/whitecx/pythonStuff/microblog/venv/lib/python3.6/site-packages/flask/_compat.py", line 33, in reraise
    raise value
  File "/home/whitecx/pythonStuff/microblog/venv/lib/python3.6/site-packages/flask/app.py", line 1612, in full_dispatch_request
    rv = self.dispatch_request()
  File "/home/whitecx/pythonStuff/microblog/venv/lib/python3.6/site-packages/flask/app.py", line 1598, in dispatch_request
    return self.view_functions[rule.endpoint](**req.view_args)
  File "/home/whitecx/pythonStuff/microblog/venv/lib/python3.6/site-packages/flask_login/utils.py", line 261, in decorated_view
    return func(*args, **kwargs)
  File "/home/whitecx/pythonStuff/microblog/app/main/routes.py", line 133, in translate_text
    request.form['dest_language'])})
  File "/home/whitecx/pythonStuff/microblog/app/translate.py", line 8, in translate
    ,dest=dest_language).text
  File "/home/whitecx/pythonStuff/microblog/venv/lib/python3.6/site-packages/googletrans/client.py", line 132, in translate
    data = self._translate(text, dest, src)
  File "/home/whitecx/pythonStuff/microblog/venv/lib/python3.6/site-packages/googletrans/client.py", line 57, in _translate
    token = self.token_acquirer.do(text)
  File "/home/whitecx/pythonStuff/microblog/venv/lib/python3.6/site-packages/googletrans/gtoken.py", line 180, in do
    self._update()
  File "/home/whitecx/pythonStuff/microblog/venv/lib/python3.6/site-packages/googletrans/gtoken.py", line 59, in _update
    code = unicode(self.RE_TKK.search(r.text).group(1)).replace('var ', '')
AttributeError: 'NoneType' object has no attribute 'group'
2019-02-22 10:25:57,328 INFO: Microblog startup [in /home/whitecx/pythonStuff/microblog/app/__init__.py:90]
2019-02-22 10:28:51,459 ERROR: Exception on /api/users/1/followed [GET] [in /home/whitecx/pythonStuff/microblog/venv/lib/python3.6/site-packages/flask/app.py:1560]
Traceback (most recent call last):
  File "/home/whitecx/pythonStuff/microblog/venv/lib/python3.6/site-packages/flask/app.py", line 1982, in wsgi_app
    response = self.full_dispatch_request()
  File "/home/whitecx/pythonStuff/microblog/venv/lib/python3.6/site-packages/flask/app.py", line 1615, in full_dispatch_request
    return self.finalize_request(rv)
  File "/home/whitecx/pythonStuff/microblog/venv/lib/python3.6/site-packages/flask/app.py", line 1630, in finalize_request
    response = self.make_response(rv)
  File "/home/whitecx/pythonStuff/microblog/venv/lib/python3.6/site-packages/flask/app.py", line 1725, in make_response
    raise ValueError('View function did not return a response')
ValueError: View function did not return a response
2019-02-22 10:29:25,845 ERROR: Exception on /api/users/1/followed [GET] [in /home/whitecx/pythonStuff/microblog/venv/lib/python3.6/site-packages/flask/app.py:1560]
Traceback (most recent call last):
  File "/home/whitecx/pythonStuff/microblog/venv/lib/python3.6/site-packages/flask/app.py", line 1982, in wsgi_app
    response = self.full_dispatch_request()
  File "/home/whitecx/pythonStuff/microblog/venv/lib/python3.6/site-packages/flask/app.py", line 1615, in full_dispatch_request
    return self.finalize_request(rv)
  File "/home/whitecx/pythonStuff/microblog/venv/lib/python3.6/site-packages/flask/app.py", line 1630, in finalize_request
    response = self.make_response(rv)
  File "/home/whitecx/pythonStuff/microblog/venv/lib/python3.6/site-packages/flask/app.py", line 1725, in make_response
    raise ValueError('View function did not return a response')
ValueError: View function did not return a response
2019-02-22 10:33:00,636 INFO: Microblog startup [in /home/whitecx/pythonStuff/microblog/app/__init__.py:90]
